<?xml version="1.0" encoding="utf-8"?>
<!-- This URDF was automatically created by SolidWorks to URDF Exporter! Originally created by Stephen Brawner (brawner@gmail.com) 
     Commit Version: 1.6.0-4-g7f85cfe  Build Version: 1.6.7995.38578
     For more information, please see http://wiki.ros.org/sw_urdf_exporter -->
<robot
  name="ra6a">
  <link
    name="base_link">
    <inertial>
      <origin
        xyz="0 0 0"
        rpy="0 0 0" />
      <mass
        value="2.915" />
      <inertia
        ixx="0.01436"
        ixy="-9.7839E-06"
        ixz="8.8797E-08"
        iyy="0.016743"
        iyz="-8.9882E-08"
        izz="0.017881" />
    </inertial>
    <visual>
      <origin
        xyz="0 0 0"
        rpy="0 0 0" />
      <geometry>
        <mesh
          filename="package://ra6a/meshes/base_link.stl" 
          scale="1.0 1.0 1.0"/>
      </geometry>
      <material
        name="">
        <color
          rgba="1 1 1 1" />
      </material>
    </visual>
    <collision>
      <origin
        xyz="0 0 0"
        rpy="0 0 0" />
      <geometry>
        <mesh
          filename="package://ra6a/meshes/base_link.stl" 
          scale="1.0 1.0 1.0"/>
      </geometry>
    </collision>
  </link>
  <link
    name="l1">
    <inertial>
      <origin
        xyz="-0.018341 -0.038699 -0.09919"
        rpy="0 0 0" />
      <mass
        value="2.4989" />
      <inertia
        ixx="0.013037"
        ixy="-0.0027249"
        ixz="0.001464"
        iyy="0.010527"
        iyz="0.0022131"
        izz="0.010986" />
    </inertial>
    <visual>
      <origin
        xyz="0 0 0"
        rpy="0 0 0" />
      <geometry>
        <mesh
          filename="package://ra6a/meshes/l1.stl" 
          scale="1.0 1.0 1.0"/>
      </geometry>
      <material
        name="">
        <color
          rgba="0.79216 0.81961 0.93333 1" />
      </material>
    </visual>
    <collision>
      <origin
        xyz="0 0 0"
        rpy="0 0 0" />
      <geometry>
        <mesh
          filename="package://ra6a/meshes/l1.stl"
          scale="1.0 1.0 1.0" />
      </geometry>
    </collision>
  </link>
  <joint
    name="j1"
    type="revolute">
    <origin
      xyz="0.11229 -0.03609 0.1369"
      rpy="3.1416 0 1.5708" />
    <parent
      link="base_link" />
    <child
      link="l1" />
    <axis
      xyz="0 0 1" />
    <limit
      lower="-3.0979"
      upper="3.0979"
      effort="55.5"
      velocity="1.05" />
  </joint>
  <link
    name="l2">
    <inertial>
      <origin
        xyz="-0.074795 0.06129 -0.10126"
        rpy="0 0 0" />
      <mass
        value="3.5609" />
      <inertia
        ixx="0.021496"
        ixy="0.00028586"
        ixz="0.00088645"
        iyy="0.031862"
        iyz="0.0004388"
        izz="0.017196" />
    </inertial>
    <visual>
      <origin
        xyz="0 0 0"
        rpy="0 0 0" />
      <geometry>
        <mesh
          filename="package://ra6a/meshes/l2.stl" 
          scale="1.0 1.0 1.0"/>
      </geometry>
      <material
        name="">
        <color
          rgba="1 1 1 1" />
      </material>
    </visual>
    <collision>
      <origin
        xyz="0 0 0"
        rpy="0 0 0" />
      <geometry>
        <mesh
          filename="package://ra6a/meshes/l2.stl" 
          scale="1.0 1.0 1.0"/>
      </geometry>
    </collision>
  </link>
  <joint
    name="j2"
    type="revolute">
    <origin
      xyz="0.038867 -0.059201 -0.33764"
      rpy="0.93632 0 -0.23845" />
    <parent
      link="l1" />
    <child
      link="l2" />
    <axis
      xyz="1 0 0" />
    <limit
      lower="-1.5708"
      upper="1.8326"
      effort="110"
      velocity="1.05" />
  </joint>
  <link
    name="l3">
    <inertial>
      <origin
        xyz="-0.049486 0.00072803 0.094"
        rpy="0 0 0" />
      <mass
        value="3.1038" />
      <inertia
        ixx="0.013328"
        ixy="4.3048E-05"
        ixz="-8.438E-05"
        iyy="0.016047"
        iyz="0.00018895"
        izz="0.0094678" />
    </inertial>
    <visual>
      <origin
        xyz="0 0 0"
        rpy="0 0 0" />
      <geometry>
        <mesh
          filename="package://ra6a/meshes/l3.stl" 
          scale="1.0 1.0 1.0"/>
      </geometry>
      <material
        name="">
        <color
          rgba="0.79608 0.82353 0.93725 1" />
      </material>
    </visual>
    <collision>
      <origin
        xyz="0 0 0"
        rpy="0 0 0" />
      <geometry>
        <mesh
          filename="package://ra6a/meshes/l3.stl" 
          scale="1.0 1.0 1.0"/>
      </geometry>
    </collision>
  </link>
  <joint
    name="j3"
    type="revolute">
    <origin
      xyz="-0.051751 0.065262 -0.17987"
      rpy="-3.1182 0 -3.1416" />
    <parent
      link="l2" />
    <child
      link="l3" />
    <axis
      xyz="1 0 0" />
    <limit
      lower="-1.9634954"
      upper="1.9634954"
      effort="65"
      velocity="1.05" />
  </joint>
  <link
    name="l4">
    <inertial>
      <origin
        xyz="-0.0064465 0.00019408 0.054263"
        rpy="0 0 0" />
      <mass
        value="0.72283" />
      <inertia
        ixx="0.0016231"
        ixy="-3.7592E-06"
        ixz="-1.0915E-05"
        iyy="0.0031796"
        iyz="-1.091E-06"
        izz="0.0024777" />
    </inertial>
    <visual>
      <origin
        xyz="0 0 0"
        rpy="0 0 0" />
      <geometry>
        <mesh
          filename="package://ra6a/meshes/l4.stl" 
          scale="1.0 1.0 1.0"/>
      </geometry>
      <material
        name="">
        <color
          rgba="0.79608 0.82353 0.93725 1" />
      </material>
    </visual>
    <collision>
      <origin
        xyz="0 0 0"
        rpy="0 0 0" />
      <geometry>
        <mesh
          filename="package://ra6a/meshes/l4.stl" 
          scale="1.0 1.0 1.0"/>
      </geometry>
    </collision>
  </link>
  <joint
    name="j4"
    type="revolute">
    <origin
      xyz="5.5E-05 1.9679E-05 0.2525"
      rpy="0 0 -3.1366" />
    <parent
      link="l3" />
    <child
      link="l4" />
    <axis
      xyz="0 0 1" />
    <limit
      lower="-3.0979"
      upper="3.0979"
      effort="20"
      velocity="1.05" />
  </joint>
  <link
    name="l5">
    <inertial>
      <origin
        xyz="0.077494 0.00023934 0.047525"
        rpy="0 0 0" />
      <mass
        value="0.59888" />
      <inertia
        ixx="0.00051226"
        ixy="5.4361E-07"
        ixz="-2.0014E-05"
        iyy="0.00074482"
        iyz="-1.971E-07"
        izz="0.00065835" />
    </inertial>
    <visual>
      <origin
        xyz="0 0 0"
        rpy="0 0 0" />
      <geometry>
        <mesh
          filename="package://ra6a/meshes/l5.stl" 
          scale="1.0 1.0 1.0"/>
      </geometry>
      <material
        name="">
        <color
          rgba="1 1 1 1" />
      </material>
    </visual>
    <collision>
      <origin
        xyz="0 0 0"
        rpy="0 0 0" />
      <geometry>
        <mesh
          filename="package://ra6a/meshes/l5.stl" 
          scale="1.0 1.0 1.0"/>
      </geometry>
    </collision>
  </link>
  <joint
    name="j5"
    type="revolute">
    <origin
      xyz="-0.0435 -0.00031432 0.089001"
      rpy="-0.0057674 0 0" />
    <parent
      link="l4" />
    <child
      link="l5" />
    <axis
      xyz="1 0 0" />
    <limit
      lower="-2.26893"
      upper="2.26893"
      effort="7"
      velocity="1.05" />
  </joint>
  <link
    name="end_effector">
    <inertial>
      <origin
        xyz="1.0858E-08 3.2998E-06 -0.0020815"
        rpy="0 0 0" />
      <mass
        value="0.010728" />
      <inertia
        ixx="1.2754E-06"
        ixy="-6.705E-13"
        ixz="-1.0633E-12"
        iyy="1.9358E-06"
        iyz="-1.5271E-10"
        izz="2.32E-06" />
    </inertial>
    <visual>
      <origin
        xyz="0 0 0"
        rpy="0 0 0" />
      <geometry>
        <mesh
          filename="package://ra6a/meshes/end_effector.stl" 
          scale="1.0 1.0 1.0"/>
      </geometry>
      <material
        name="">
        <color
          rgba="0.79216 0.81961 0.93333 1" />
      </material>
    </visual>
    <collision>
      <origin
        xyz="0 0 0"
        rpy="0 0 0" />
      <geometry>
        <mesh
          filename="package://ra6a/meshes/end_effector.stl" 
          scale="1.0 1.0 1.0"/>
      </geometry>
    </collision>
  </link>
  <joint
    name="j6"
    type="revolute">
    <origin
      xyz="0.0435 0 0.1025"
      rpy="0 0 -1.5764" />
    <parent
      link="l5" />
    <child
      link="end_effector" />
    <axis
      xyz="0 0 1" />
    <limit
      lower="-3.0979"
      upper="3.0979"
      effort="1.8"
      velocity="1.05" />
  </joint>
</robot>
